Workbook

Sheet LANDSAT_results_0_General
C1: bandCount Normalized Endmembers | K1: General Gram Matrix
C2: 1 | D2: 2 | E2: 3 | F2: 4 | G2: 5 | H2: 6 | I2: 7 | L2: 1 | M2: 2 | N2: 3 | O2: 4 | P2: 5 | Q2: 6 | R2: 7 | U2: wavelength | V2: meanEndmember
A3: wavelengths | B3: 0.443 | C3: =C38/$B$11 -> 1 | D3: =D38/$B$11 -> 0.01 | E3: =E38/$B$11 -> 1 | F3: =F38/$B$11 -> 0 | G3: =G38/$B$11 -> 0 | H3: =H38/$B$11 -> 1 | I3: =I38/$B$11 -> 1 | K3: 1 | L3: =SUMPRODUCT($C3:$C9,C3:C9) -> 4 | M3: =SUMPRODUCT($C3:$C9,D3:D9) -> 0.04 | N3: =SUMPRODUCT($C3:$C9,E3:E9) -> 2 | O3: =SUMPRODUCT($C3:$C9,F3:F9) -> 2 | P3: =SUMPRODUCT($C3:$C9,G3:G9) -> 2 | Q3: =SUMPRODUCT($C3:$C9,H3:H9) -> 2 | R3: =SUMPRODUCT($C3:$C9,I3:I9) -> 2 | U3: 0.443 | V3: 0.2
B4: 0.482 | C4: =C39/$B$11 -> 0 | D4: =D39/$B$11 -> 0.01 | E4: =E39/$B$11 -> 1 | F4: =F39/$B$11 -> 1 | G4: =G39/$B$11 -> 0 | H4: =H39/$B$11 -> 0 | I4: =I39/$B$11 -> 1 | K4: 2 | L4: =SUMPRODUCT($D3:$D9,C3:C9) -> 0.04 | M4: =SUMPRODUCT($D3:$D9,D3:D9) -> 0.0007 | N4: =SUMPRODUCT($D3:$D9,E3:E9) -> 0.04 | O4: =SUMPRODUCT($D3:$D9,F3:F9) -> 0.04 | P4: =SUMPRODUCT($D3:$D9,G3:G9) -> 0.03 | Q4: =SUMPRODUCT($D3:$D9,H3:H9) -> 0.04 | R4: =SUMPRODUCT($D3:$D9,I3:I9) -> 0.04 | U4: 0.482 | V4: 0.2
B5: 0.561 | C5: =C40/$B$11 -> 1 | D5: =D40/$B$11 -> 0.01 | E5: =E40/$B$11 -> 0 | F5: =F40/$B$11 -> 0 | G5: =G40/$B$11 -> 1 | H5: =H40/$B$11 -> 0 | I5: =I40/$B$11 -> 1 | K5: 3 | L5: =SUMPRODUCT($E3:$E9,C3:C9) -> 2 | M5: =SUMPRODUCT($E3:$E9,D3:D9) -> 0.04 | N5: =SUMPRODUCT($E3:$E9,E3:E9) -> 4 | O5: =SUMPRODUCT($E3:$E9,F3:F9) -> 2 | P5: =SUMPRODUCT($E3:$E9,G3:G9) -> 1 | Q5: =SUMPRODUCT($E3:$E9,H3:H9) -> 2 | R5: =SUMPRODUCT($E3:$E9,I3:I9) -> 2 | U5: 0.561 | V5: 0.2
B6: 0.655 | C6: =C41/$B$11 -> 1 | D6: =D41/$B$11 -> 0.01 | E6: =E41/$B$11 -> 0 | F6: =F41/$B$11 -> 1 | G6: =G41/$B$11 -> 1 | H6: =H41/$B$11 -> 1 | I6: =I41/$B$11 -> 0 | K6: 4 | L6: =SUMPRODUCT($F3:$F9,C3:C9) -> 2 | M6: =SUMPRODUCT($F3:$F9,D3:D9) -> 0.04 | N6: =SUMPRODUCT($F3:$F9,E3:E9) -> 2 | O6: =SUMPRODUCT($F3:$F9,F3:F9) -> 4 | P6: =SUMPRODUCT($F3:$F9,G3:G9) -> 1 | Q6: =SUMPRODUCT($F3:$F9,H3:H9) -> 2 | R6: =SUMPRODUCT($F3:$F9,I3:I9) -> 2 | U6: 0.655 | V6: 0.2
B7: 0.865 | C7: =C42/$B$11 -> 0 | D7: =D42/$B$11 -> 0.01 | E7: =E42/$B$11 -> 1 | F7: =F42/$B$11 -> 0 | G7: =G42/$B$11 -> 1 | H7: =H42/$B$11 -> 1 | I7: =I42/$B$11 -> 0 | K7: 5 | L7: =SUMPRODUCT($G3:$G9,C3:C9) -> 2 | M7: =SUMPRODUCT($G3:$G9,D3:D9) -> 0.03 | N7: =SUMPRODUCT($G3:$G9,E3:E9) -> 1 | O7: =SUMPRODUCT($G3:$G9,F3:F9) -> 1 | P7: =SUMPRODUCT($G3:$G9,G3:G9) -> 3 | Q7: =SUMPRODUCT($G3:$G9,H3:H9) -> 2 | R7: =SUMPRODUCT($G3:$G9,I3:I9) -> 1 | U7: 0.865 | V7: 0.2
B8: 1.609 | C8: =C43/$B$11 -> 1 | D8: =D43/$B$11 -> 0.01 | E8: =E43/$B$11 -> 1 | F8: =F43/$B$11 -> 1 | G8: =G43/$B$11 -> 0 | H8: =H43/$B$11 -> 0 | I8: =I43/$B$11 -> 0 | K8: 6 | L8: =SUMPRODUCT($H3:$H9,C3:C9) -> 2 | M8: =SUMPRODUCT($H3:$H9,D3:D9) -> 0.04 | N8: =SUMPRODUCT($H3:$H9,E3:E9) -> 2 | O8: =SUMPRODUCT($H3:$H9,F3:F9) -> 2 | P8: =SUMPRODUCT($H3:$H9,G3:G9) -> 2 | Q8: =SUMPRODUCT($H3:$H9,H3:H9) -> 4 | R8: =SUMPRODUCT($H3:$H9,I3:I9) -> 2 | U8: 1.609 | V8: 0.2
B9: 2.201 | C9: =C44/$B$11 -> 0 | D9: =D44/$B$11 -> 0.01 | E9: =E44/$B$11 -> 0 | F9: =F44/$B$11 -> 1 | G9: =G44/$B$11 -> 0 | H9: =H44/$B$11 -> 1 | I9: =I44/$B$11 -> 1 | K9: 7 | L9: =SUMPRODUCT($I3:$I9,C3:C9) -> 2 | M9: =SUMPRODUCT($I3:$I9,D3:D9) -> 0.04 | N9: =SUMPRODUCT($I3:$I9,E3:E9) -> 2 | O9: =SUMPRODUCT($I3:$I9,F3:F9) -> 2 | P9: =SUMPRODUCT($I3:$I9,G3:G9) -> 1 | Q9: =SUMPRODUCT($I3:$I9,H3:H9) -> 2 | R9: =SUMPRODUCT($I3:$I9,I3:I9) -> 4 | U9: 2.201 | V9: 0.2
A11: Scale Val | B11: 1 | L11: 1 | M11: 2 | N11: 3 | O11: 4 | P11: 5 | Q11: 6 | R11: 7
L12: =MDETERM(L3) -> 4 | M12: =MDETERM(L3:M4) -> 0.0012 | N12: =MDETERM(L3:N5) -> 0.002 | O12: =MDETERM(L3:O6) -> 0.0032 | P12: =MDETERM(L3:P7) -> 0.0032 | Q12: =MDETERM(L3:Q8) -> 0.0048 | R12: =MDETERM(L3:R9) -> 0.0016
L13: =SQRT(L12) -> 2 | M13: =SQRT(M12) -> 0.034641016 | N13: =SQRT(N12) -> 0.04472136 | O13: =SQRT(O12) -> 0.056568542 | P13: =SQRT(P12) -> 0.056568542 | Q13: =SQRT(Q12) -> 0.069282032 | R13: =SQRT(R12) -> 0.04
B15: Real Data General Gram Matrix | K15: Real Data Dataset Mean Localized Gram Matrix | V15: meanEndmember Localized Endmembers | AE15: meanEndmember Localized Gram Matrix
C16: 1 | D16: 2 | E16: 3 | F16: 4 | G16: 5 | H16: 6 | I16: 7 | L16: 1 | M16: 2 | N16: 3 | O16: 4 | P16: 5 | Q16: 6 | R16: 7 | V16: 1 | W16: 2 | X16: 3 | Y16: 4 | Z16: 5 | AA16: 6 | AB16: 7 | AE16: 1 | AF16: 2 | AG16: 3 | AH16: 4 | AI16: 5 | AJ16: 6 | AK16: 7
B17: 1 | C17: 0.23991863 | D17: 0.0047062541 | E17: 0.16866283 | F17: 0.20872728 | G17: 0.056445945 | H17: 0.14839604 | I17: 0.20393331 | K17: 1 | L17: 0.0061 | M17: -0.007 | N17: -0.0024 | O17: 0.0049 | P17: 0.002 | Q17: -0.0027 | R17: 0.0021 | T17: wavelengths | U17: 0.443 | V17: =C3-$V$3 -> 0.8 | W17: =D3-$V3 -> -0.19 | X17: =E3-$V3 -> 0.8 | Y17: =F3-$V3 -> -0.2 | Z17: =G3-$V3 -> -0.2 | AA17: =H3-$V3 -> 0.8 | AB17: =I3-$V3 -> 0.8 | AD17: 1 | AE17: =SUMPRODUCT($V17:$V23,V17:V23) -> 2.68 | AF17: =SUMPRODUCT($V17:$V23,W17:W23) -> -0.494 | AG17: =SUMPRODUCT($V17:$V23,X17:X23) -> 0.68 | AH17: =SUMPRODUCT($V17:$V23,Y17:Y23) -> 0.68 | AI17: =SUMPRODUCT($V17:$V23,Z17:Z23) -> 0.88 | AJ17: =SUMPRODUCT($V17:$V23,AA17:AA23) -> 0.68 | AK17: =SUMPRODUCT($V17:$V23,AB17:AB23) -> 0.68
B18: 2 | C18: 0.0047062541 | D18: 0.0005633791 | E18: 0.0029620674 | F18: 0.0049506242 | G18: 0.0019440586 | H18: 0.0034949931 | I18: 0.003857498 | K18: 2 | L18: -0.007 | M18: 0.0089 | N18: 0.0023 | O18: -0.0054 | P18: -0.0026 | Q18: 0.0036 | R18: -0.0032 | U18: 0.482 | V18: =C4-$V4 -> -0.2 | W18: =D4-$V4 -> -0.19 | X18: =E4-$V4 -> 0.8 | Y18: =F4-$V4 -> 0.8 | Z18: =G4-$V4 -> -0.2 | AA18: =H4-$V4 -> -0.2 | AB18: =I4-$V4 -> 0.8 | AD18: 2 | AE18: =SUMPRODUCT($W17:$W23,V17:V23) -> -0.494 | AF18: =SUMPRODUCT($W17:$W23,W17:W23) -> 0.2527 | AG18: =SUMPRODUCT($W17:$W23,X17:X23) -> -0.494 | AH18: =SUMPRODUCT($W17:$W23,Y17:Y23) -> -0.494 | AI18: =SUMPRODUCT($W17:$W23,Z17:Z23) -> -0.304 | AJ18: =SUMPRODUCT($W17:$W23,AA17:AA23) -> -0.494 | AK18: =SUMPRODUCT($W17:$W23,AB17:AB23) -> -0.494
B19: 3 | C19: 0.16866283 | D19: 0.0029620674 | E19: 0.15242708 | F19: 0.14508558 | G19: 0.044836797 | H19: 0.11320952 | I19: 0.15877856 | K19: 3 | L19: -0.0024 | M19: 0.0023 | N19: 0.0013 | O19: -0.0021 | P19: -0.0006 | Q19: 0.0008 | R19: -0.0004 | U19: 0.561 | V19: =C5-$V5 -> 0.8 | W19: =D5-$V5 -> -0.19 | X19: =E5-$V5 -> -0.2 | Y19: =F5-$V5 -> -0.2 | Z19: =G5-$V5 -> 0.8 | AA19: =H5-$V5 -> -0.2 | AB19: =I5-$V5 -> 0.8 | AD19: 3 | AE19: =SUMPRODUCT($X17:$X23,V17:V23) -> 0.68 | AF19: =SUMPRODUCT($X17:$X23,W17:W23) -> -0.494 | AG19: =SUMPRODUCT($X17:$X23,X17:X23) -> 2.68 | AH19: =SUMPRODUCT($X17:$X23,Y17:Y23) -> 0.68 | AI19: =SUMPRODUCT($X17:$X23,Z17:Z23) -> -0.12 | AJ19: =SUMPRODUCT($X17:$X23,AA17:AA23) -> 0.68 | AK19: =SUMPRODUCT($X17:$X23,AB17:AB23) -> 0.68
B20: 4 | C20: 0.20872728 | D20: 0.0049506242 | E20: 0.14508558 | F20: 0.18552307 | G20: 0.050839433 | H20: 0.13050844 | I20: 0.17685325 | K20: 4 | L20: 0.0049 | M20: -0.0054 | N20: -0.0021 | O20: 0.0041 | P20: 0.0015 | Q20: -0.0021 | R20: 0.0015 | U20: 0.655 | V20: =C6-$V6 -> 0.8 | W20: =D6-$V6 -> -0.19 | X20: =E6-$V6 -> -0.2 | Y20: =F6-$V6 -> 0.8 | Z20: =G6-$V6 -> 0.8 | AA20: =H6-$V6 -> 0.8 | AB20: =I6-$V6 -> -0.2 | AD20: 4 | AE20: =SUMPRODUCT($Y17:$Y23,V17:V23) -> 0.68 | AF20: =SUMPRODUCT($Y17:$Y23,W17:W23) -> -0.494 | AG20: =SUMPRODUCT($Y17:$Y23,X17:X23) -> 0.68 | AH20: =SUMPRODUCT($Y17:$Y23,Y17:Y23) -> 2.68 | AI20: =SUMPRODUCT($Y17:$Y23,Z17:Z23) -> -0.12 | AJ20: =SUMPRODUCT($Y17:$Y23,AA17:AA23) -> 0.68 | AK20: =SUMPRODUCT($Y17:$Y23,AB17:AB23) -> 0.68
B21: 5 | C21: 0.056445945 | D21: 0.0019440586 | E21: 0.044836797 | F21: 0.050839433 | G21: 0.016044446 | H21: 0.037572289 | I21: 0.050327565 | K21: 5 | L21: 0.002 | M21: -0.0026 | N21: -0.0006 | O21: 0.0015 | P21: 0.0008 | Q21: -0.0011 | R21: 0.001 | U21: 0.865 | V21: =C7-$V7 -> -0.2 | W21: =D7-$V7 -> -0.19 | X21: =E7-$V7 -> 0.8 | Y21: =F7-$V7 -> -0.2 | Z21: =G7-$V7 -> 0.8 | AA21: =H7-$V7 -> 0.8 | AB21: =I7-$V7 -> -0.2 | AD21: 5 | AE21: =SUMPRODUCT($Z17:$Z23,V17:V23) -> 0.88 | AF21: =SUMPRODUCT($Z17:$Z23,W17:W23) -> -0.304 | AG21: =SUMPRODUCT($Z17:$Z23,X17:X23) -> -0.12 | AH21: =SUMPRODUCT($Z17:$Z23,Y17:Y23) -> -0.12 | AI21: =SUMPRODUCT($Z17:$Z23,Z17:Z23) -> 2.08 | AJ21: =SUMPRODUCT($Z17:$Z23,AA17:AA23) -> 0.88 | AK21: =SUMPRODUCT($Z17:$Z23,AB17:AB23) -> -0.12
B22: 6 | C22: 0.14839604 | D22: 0.0034949931 | E22: 0.11320952 | F22: 0.13050844 | G22: 0.037572289 | H22: 0.095301123 | I22: 0.1302533 | K22: 6 | L22: -0.0027 | M22: 0.0036 | N22: 0.0008 | O22: -0.0021 | P22: -0.0011 | Q22: 0.0014 | R22: -0.0013 | U22: 1.609 | V22: =C8-$V8 -> 0.8 | W22: =D8-$V8 -> -0.19 | X22: =E8-$V8 -> 0.8 | Y22: =F8-$V8 -> 0.8 | Z22: =G8-$V8 -> -0.2 | AA22: =H8-$V8 -> -0.2 | AB22: =I8-$V8 -> -0.2 | AD22: 6 | AE22: =SUMPRODUCT($AA17:$AA23,V17:V23) -> 0.68 | AF22: =SUMPRODUCT($AA17:$AA23,W17:W23) -> -0.494 | AG22: =SUMPRODUCT($AA17:$AA23,X17:X23) -> 0.68 | AH22: =SUMPRODUCT($AA17:$AA23,Y17:Y23) -> 0.68 | AI22: =SUMPRODUCT($AA17:$AA23,Z17:Z23) -> 0.88 | AJ22: =SUMPRODUCT($AA17:$AA23,AA17:AA23) -> 2.68 | AK22: =SUMPRODUCT($AA17:$AA23,AB17:AB23) -> 0.68
B23: 7 | C23: 0.20393331 | D23: 0.003857498 | E23: 0.15877856 | F23: 0.17685325 | G23: 0.050327565 | H23: 0.1302533 | I23: 0.18040496 | K23: 7 | L23: 0.0021 | M23: -0.0032 | N23: -0.0004 | O23: 0.0015 | P23: 0.001 | Q23: -0.0013 | R23: 0.0014 | U23: 2.201 | V23: =C9-$V9 -> -0.2 | W23: =D9-$V9 -> -0.19 | X23: =E9-$V9 -> -0.2 | Y23: =F9-$V9 -> 0.8 | Z23: =G9-$V9 -> -0.2 | AA23: =H9-$V9 -> 0.8 | AB23: =I9-$V9 -> 0.8 | AD23: 7 | AE23: =SUMPRODUCT($AB17:$AB23,V17:V23) -> 0.68 | AF23: =SUMPRODUCT($AB17:$AB23,W17:W23) -> -0.494 | AG23: =SUMPRODUCT($AB17:$AB23,X17:X23) -> 0.68 | AH23: =SUMPRODUCT($AB17:$AB23,Y17:Y23) -> 0.68 | AI23: =SUMPRODUCT($AB17:$AB23,Z17:Z23) -> -0.12 | AJ23: =SUMPRODUCT($AB17:$AB23,AA17:AA23) -> 0.68 | AK23: =SUMPRODUCT($AB17:$AB23,AB17:AB23) -> 2.68
AE25: 1 | AF25: 2 | AG25: 3 | AH25: 4 | AI25: 5 | AJ25: 6 | AK25: 7
B26: Real General Volume Estimations | K26: Real Dataset Mean Localized Volume Estimations | AD26: Determinant | AE26: =MDETERM(AE17) -> 2.68 | AF26: =MDETERM(AE17:AF18) -> 0.4332 | AG26: =MDETERM(AE17:AG19) -> 0.722 | AH26: =MDETERM(AE17:AH20) -> 1.1552 | AI26: =MDETERM(AE17:AI21) -> 1.1552 | AJ26: =MDETERM(AE17:AJ22) -> 1.7328 | AK26: =MDETERM(AE17:AK23) -> 0.5776
B27: 1 | C27: 2 | D27: 3 | E27: 4 | F27: 5 | G27: 6 | H27: 7 | K27: 1 | L27: 2 | M27: 3 | N27: 4 | O27: 5 | P27: 6 | Q27: 7 | AD27: Volume | AE27: =SQRT(AE26) -> 1.6370706 | AF27: =SQRT(AF26) -> 0.65817931 | AG27: =SQRT(AG26) -> 0.84970583 | AH27: =SQRT(AH26) -> 1.0748023 | AI27: =SQRT(AI26) -> 1.0748023 | AJ27: =SQRT(AJ26) -> 1.3163586 | AK27: =SQRT(AK26) -> 0.76
B28: 0.48981489 | C28: 0.010630913 | D28: 0.0019487454 | E28: 9.4363009e-05 | F28: 1.4097487e-06 | G28: 4.4112659e-09 | H28: 6.255918e-13 | K28: 0.078 | L28: 0.002 | M28: 1.05e-05 | N28: 4.48e-08 | O28: 6.61e-11 | P28: 6.28e-14 | Q28: 3.93e-17
B30: det(G) | D30: =MDETERM(C17:F20) -> 8.9043776e-09
B31: sqrt(det(G)) | D31: =SQRT(D30) -> 9.4363009e-05
M33: minEndmember Localized Endmembers | V33: minEndmember Localized Gram Matrix
M34: 1 | N34: X | O34: 3 | P34: 4 | Q34: 5 | R34: 6 | S34: 7 | V34: 1 | W34: 2 | X34: 3 | Y34: 4 | Z34: 5 | AA34: 6
K35: wavelengths | L35: 0.443 | M35: =C3-$D$3 -> 0.99 | N35: =D3-$D3 -> 0 | O35: =E3-$D3 -> 0.99 | P35: =F3-$D3 -> -0.01 | Q35: =G3-$D3 -> -0.01 | R35: =H3-$D3 -> 0.99 | S35: =I3-$D3 -> 0.99 | U35: 1 | V35: =SUMPRODUCT($M35:$M41,M35:M41) -> 3.9207 | W35: =SUMPRODUCT($M35:$M41,O35:O41) -> 1.9207 | X35: =SUMPRODUCT($M35:$M41,P35:P41) -> 1.9207 | Y35: =SUMPRODUCT($M35:$M41,Q35:Q41) -> 1.9307 | Z35: =SUMPRODUCT($M35:$M41,R35:R41) -> 1.9207 | AA35: =SUMPRODUCT($M35:$M41,S35:S41) -> 1.9207
C36: Test Endmembers | L36: 0.482 | M36: =C4-$D$3 -> -0.01 | N36: =D4-$D4 -> 0 | O36: =E4-$D4 -> 0.99 | P36: =F4-$D4 -> 0.99 | Q36: =G4-$D4 -> -0.01 | R36: =H4-$D4 -> -0.01 | S36: =I4-$D4 -> 0.99 | U36: 2 | V36: =SUMPRODUCT($O35:$O41,M35:M41) -> 1.9207 | W36: =SUMPRODUCT($O35:$O41,O35:O41) -> 3.9207 | X36: =SUMPRODUCT($O35:$O41,P35:P41) -> 1.9207 | Y36: =SUMPRODUCT($O35:$O41,Q35:Q41) -> 0.9307 | Z36: =SUMPRODUCT($O35:$O41,R35:R41) -> 1.9207 | AA36: =SUMPRODUCT($O35:$O41,S35:S41) -> 1.9207
C37: 1 | D37: 2 | E37: 3 | F37: 4 | G37: 5 | H37: 6 | I37: 7 | L37: 0.561 | M37: =C5-$D$3 -> 0.99 | N37: =D5-$D5 -> 0 | O37: =E5-$D5 -> -0.01 | P37: =F5-$D5 -> -0.01 | Q37: =G5-$D5 -> 0.99 | R37: =H5-$D5 -> -0.01 | S37: =I5-$D5 -> 0.99 | U37: 3 | V37: =SUMPRODUCT($P35:$P41,M35:M41) -> 1.9207 | W37: =SUMPRODUCT($P35:$P41,O35:O41) -> 1.9207 | X37: =SUMPRODUCT($P35:$P41,P35:P41) -> 3.9207 | Y37: =SUMPRODUCT($P35:$P41,Q35:Q41) -> 0.9307 | Z37: =SUMPRODUCT($P35:$P41,R35:R41) -> 1.9207 | AA37: =SUMPRODUCT($P35:$P41,S35:S41) -> 1.9207
A38: wavelengths | B38: 0.443 | C38: 1 | D38: 0.01 | E38: 1 | F38: 0 | G38: 0 | H38: 1 | I38: 1 | L38: 0.655 | M38: =C6-$D$3 -> 0.99 | N38: =D6-$D6 -> 0 | O38: =E6-$D6 -> -0.01 | P38: =F6-$D6 -> 0.99 | Q38: =G6-$D6 -> 0.99 | R38: =H6-$D6 -> 0.99 | S38: =I6-$D6 -> -0.01 | U38: 4 | V38: =SUMPRODUCT($Q35:$Q41,M35:M41) -> 1.9307 | W38: =SUMPRODUCT($Q35:$Q41,O35:O41) -> 0.9307 | X38: =SUMPRODUCT($Q35:$Q41,P35:P41) -> 0.9307 | Y38: =SUMPRODUCT($Q35:$Q41,Q35:Q41) -> 2.9407 | Z38: =SUMPRODUCT($Q35:$Q41,R35:R41) -> 1.9307 | AA38: =SUMPRODUCT($Q35:$Q41,S35:S41) -> 0.9307
B39: 0.482 | C39: 0 | D39: 0.01 | E39: 1 | F39: 1 | G39: 0 | H39: 0 | I39: 1 | L39: 0.865 | M39: =C7-$D$3 -> -0.01 | N39: =D7-$D7 -> 0 | O39: =E7-$D7 -> 0.99 | P39: =F7-$D7 -> -0.01 | Q39: =G7-$D7 -> 0.99 | R39: =H7-$D7 -> 0.99 | S39: =I7-$D7 -> -0.01 | U39: 5 | V39: =SUMPRODUCT($R35:$R41,M35:M41) -> 1.9207 | W39: =SUMPRODUCT($R35:$R41,O35:O41) -> 1.9207 | X39: =SUMPRODUCT($R35:$R41,P35:P41) -> 1.9207 | Y39: =SUMPRODUCT($R35:$R41,Q35:Q41) -> 1.9307 | Z39: =SUMPRODUCT($R35:$R41,R35:R41) -> 3.9207 | AA39: =SUMPRODUCT($R35:$R41,S35:S41) -> 1.9207
B40: 0.561 | C40: 1 | D40: 0.01 | E40: 0 | F40: 0 | G40: 1 | H40: 0 | I40: 1 | L40: 1.609 | M40: =C8-$D$3 -> 0.99 | N40: =D8-$D8 -> 0 | O40: =E8-$D8 -> 0.99 | P40: =F8-$D8 -> 0.99 | Q40: =G8-$D8 -> -0.01 | R40: =H8-$D8 -> -0.01 | S40: =I8-$D8 -> -0.01 | U40: 6 | V40: =SUMPRODUCT($S35:$S41,M35:M41) -> 1.9207 | W40: =SUMPRODUCT($S35:$S41,O35:O41) -> 1.9207 | X40: =SUMPRODUCT($S35:$S41,P35:P41) -> 1.9207 | Y40: =SUMPRODUCT($S35:$S41,Q35:Q41) -> 0.9307 | Z40: =SUMPRODUCT($S35:$S41,R35:R41) -> 1.9207 | AA40: =SUMPRODUCT($S35:$S41,S35:S41) -> 3.9207
B41: 0.655 | C41: 1 | D41: 0.01 | E41: 0 | F41: 1 | G41: 1 | H41: 1 | I41: 0 | L41: 2.201 | M41: =C9-$D$3 -> -0.01 | N41: =D9-$D9 -> 0 | O41: =E9-$D9 -> -0.01 | P41: =F9-$D9 -> 0.99 | Q41: =G9-$D9 -> -0.01 | R41: =H9-$D9 -> 0.99 | S41: =I9-$D9 -> 0.99
B42: 0.865 | C42: 0 | D42: 0.01 | E42: 1 | F42: 0 | G42: 1 | H42: 1 | I42: 0
B43: 1.609 | C43: 1 | D43: 0.01 | E43: 1 | F43: 1 | G43: 0 | H43: 0 | I43: 0 | V43: 1 | W43: 2 | X43: 3 | Y43: 4 | Z43: 5 | AA43: 6
B44: 2.201 | C44: 0 | D44: 0.01 | E44: 0 | F44: 1 | G44: 0 | H44: 1 | I44: 1 | U44: Determinant | V44: =MDETERM(V35) -> 3.9207 | W44: =MDETERM(V35:W36) -> 11.6828 | X44: =MDETERM(V35:X37) -> 31.0484 | Y44: =MDETERM(V35:Y38) -> 61.7812 | Z44: =MDETERM(V35:Z39) -> 123.5616 | AA44: =MDETERM(V35:AA40) -> 292.904
U45: Volume | V45: =SQRT(V44) -> 1.9800758 | W45: =SQRT(W44) -> 3.4180111 | X45: =SQRT(X44) -> 5.5721091 | Y45: =SQRT(Y44) -> 7.8601018 | Z45: =SQRT(Z44) -> 11.115827 | AA45: =SQRT(AA44) -> 17.114438
...

Sheet Volume Values
A2: Mean | B2: 3.5e-07
A3: Variance | B3: 1.32e-07
N15: =ABS(_xlfn.NORM.INV(RAND(),$B$2,SQRT($B$3))) -> 0.00013695729 | O15: =ABS(_xlfn.NORM.INV(RAND(),$B$2,SQRT($B$3))) -> 0.00029542793 | P15: =ABS(_xlfn.NORM.INV(RAND(),$B$2,SQRT($B$3))) -> 0.00021144371 | Q15: =ABS(_xlfn.NORM.INV(RAND(),$B$2,SQRT($B$3))) -> 0.0001778458 | R15: =ABS(_xlfn.NORM.INV(RAND(),$B$2,SQRT($B$3))) -> 0.00014670696 | S15: =ABS(_xlfn.NORM.INV(RAND(),$B$2,SQRT($B$3))) -> 0.00050159869 | T15: =ABS(_xlfn.NORM.INV(RAND(),$B$2,SQRT($B$3))) -> 0.00047291713 | U15: =ABS(_xlfn.NORM.INV(RAND(),$B$2,SQRT($B$3))) -> 8.6449564e-05 | ... CW15: =ABS(_xlfn.NORM.INV(RAND(),$B$2,SQRT($B$3))) -> 0.00037152836
N16: =ABS(_xlfn.NORM.INV(RAND(),$B$2,SQRT($B$3))) -> 4.550677e-05 | O16: =ABS(_xlfn.NORM.INV(RAND(),$B$2,SQRT($B$3))) -> 0.00044794803 | P16: =ABS(_xlfn.NORM.INV(RAND(),$B$2,SQRT($B$3))) -> 0.00046380616 | Q16: =ABS(_xlfn.NORM.INV(RAND(),$B$2,SQRT($B$3))) -> 0.0002729281 | R16: =ABS(_xlfn.NORM.INV(RAND(),$B$2,SQRT($B$3))) -> 0.00036964825 | S16: =ABS(_xlfn.NORM.INV(RAND(),$B$2,SQRT($B$3))) -> 0.00021599544 | T16: =ABS(_xlfn.NORM.INV(RAND(),$B$2,SQRT($B$3))) -> 0.00031747498 | U16: =ABS(_xlfn.NORM.INV(RAND(),$B$2,SQRT($B$3))) -> 0.00021876676 | ... CW16: =ABS(_xlfn.NORM.INV(RAND(),$B$2,SQRT($B$3))) -> 9.0117362e-05
N17: =ABS(_xlfn.NORM.INV(RAND(),$B$2,SQRT($B$3))) -> 0.00024877034 | O17: =ABS(_xlfn.NORM.INV(RAND(),$B$2,SQRT($B$3))) -> 0.00021538126 | P17: =ABS(_xlfn.NORM.INV(RAND(),$B$2,SQRT($B$3))) -> 0.00048979096 | Q17: =ABS(_xlfn.NORM.INV(RAND(),$B$2,SQRT($B$3))) -> 1.1333072e-05 | R17: =ABS(_xlfn.NORM.INV(RAND(),$B$2,SQRT($B$3))) -> 0.00022065097 | S17: =ABS(_xlfn.NORM.INV(RAND(),$B$2,SQRT($B$3))) -> 0.00035777153 | T17: =ABS(_xlfn.NORM.INV(RAND(),$B$2,SQRT($B$3))) -> 0.00035194515 | U17: =ABS(_xlfn.NORM.INV(RAND(),$B$2,SQRT($B$3))) -> 0.00048280484 | ... CW17: =ABS(_xlfn.NORM.INV(RAND(),$B$2,SQRT($B$3))) -> 0.00073289669
N18: =ABS(_xlfn.NORM.INV(RAND(),$B$2,SQRT($B$3))) -> 0.00013079022 | O18: =ABS(_xlfn.NORM.INV(RAND(),$B$2,SQRT($B$3))) -> 0.00056126157 | P18: =ABS(_xlfn.NORM.INV(RAND(),$B$2,SQRT($B$3))) -> 0.00039915974 | Q18: =ABS(_xlfn.NORM.INV(RAND(),$B$2,SQRT($B$3))) -> 4.3110817e-06 | R18: =ABS(_xlfn.NORM.INV(RAND(),$B$2,SQRT($B$3))) -> 0.00079000617 | S18: =ABS(_xlfn.NORM.INV(RAND(),$B$2,SQRT($B$3))) -> 0.00015993099 | T18: =ABS(_xlfn.NORM.INV(RAND(),$B$2,SQRT($B$3))) -> 0.00065276731 | U18: =ABS(_xlfn.NORM.INV(RAND(),$B$2,SQRT($B$3))) -> 0.00046261099 | ... CW18: =ABS(_xlfn.NORM.INV(RAND(),$B$2,SQRT($B$3))) -> 0.00010493344
N19: =ABS(_xlfn.NORM.INV(RAND(),$B$2,SQRT($B$3))) -> 0.00022460638 | O19: =ABS(_xlfn.NORM.INV(RAND(),$B$2,SQRT($B$3))) -> 0.00018796404 | P19: =ABS(_xlfn.NORM.INV(RAND(),$B$2,SQRT($B$3))) -> 0.00026556284 | Q19: =ABS(_xlfn.NORM.INV(RAND(),$B$2,SQRT($B$3))) -> 0.0001327139 | R19: =ABS(_xlfn.NORM.INV(RAND(),$B$2,SQRT($B$3))) -> 9.1800618e-05 | S19: =ABS(_xlfn.NORM.INV(RAND(),$B$2,SQRT($B$3))) -> 0.00055543399 | T19: =ABS(_xlfn.NORM.INV(RAND(),$B$2,SQRT($B$3))) -> 0.00011842928 | U19: =ABS(_xlfn.NORM.INV(RAND(),$B$2,SQRT($B$3))) -> 9.476123e-05 | ... CW19: =ABS(_xlfn.NORM.INV(RAND(),$B$2,SQRT($B$3))) -> 0.00036949961
N20: =ABS(_xlfn.NORM.INV(RAND(),$B$2,SQRT($B$3))) -> 0.00059157064 | O20: =ABS(_xlfn.NORM.INV(RAND(),$B$2,SQRT($B$3))) -> 3.2827903e-05 | P20: =ABS(_xlfn.NORM.INV(RAND(),$B$2,SQRT($B$3))) -> 0.00031959662 | Q20: =ABS(_xlfn.NORM.INV(RAND(),$B$2,SQRT($B$3))) -> 0.00013146084 | R20: =ABS(_xlfn.NORM.INV(RAND(),$B$2,SQRT($B$3))) -> 2.2165431e-05 | S20: =ABS(_xlfn.NORM.INV(RAND(),$B$2,SQRT($B$3))) -> 6.1102282e-05 | T20: =ABS(_xlfn.NORM.INV(RAND(),$B$2,SQRT($B$3))) -> 0.0001103994 | U20: =ABS(_xlfn.NORM.INV(RAND(),$B$2,SQRT($B$3))) -> 0.00020646225 | ... CW20: =ABS(_xlfn.NORM.INV(RAND(),$B$2,SQRT($B$3))) -> 0.00011357197
N21: =ABS(_xlfn.NORM.INV(RAND(),$B$2,SQRT($B$3))) -> 0.00046559088 | O21: =ABS(_xlfn.NORM.INV(RAND(),$B$2,SQRT($B$3))) -> 0.00011640071 | P21: =ABS(_xlfn.NORM.INV(RAND(),$B$2,SQRT($B$3))) -> 0.00011750703 | Q21: =ABS(_xlfn.NORM.INV(RAND(),$B$2,SQRT($B$3))) -> 8.060232e-05 | R21: =ABS(_xlfn.NORM.INV(RAND(),$B$2,SQRT($B$3))) -> 6.2480777e-05 | S21: =ABS(_xlfn.NORM.INV(RAND(),$B$2,SQRT($B$3))) -> 1.4985904e-05 | T21: =ABS(_xlfn.NORM.INV(RAND(),$B$2,SQRT($B$3))) -> 0.00038281031 | U21: =ABS(_xlfn.NORM.INV(RAND(),$B$2,SQRT($B$3))) -> 0.00011664254 | ... CW21: =ABS(_xlfn.NORM.INV(RAND(),$B$2,SQRT($B$3))) -> 1.6606448e-05
N22: =ABS(_xlfn.NORM.INV(RAND(),$B$2,SQRT($B$3))) -> 0.00034904317 | O22: =ABS(_xlfn.NORM.INV(RAND(),$B$2,SQRT($B$3))) -> 0.0003359237 | P22: =ABS(_xlfn.NORM.INV(RAND(),$B$2,SQRT($B$3))) -> 0.00067044662 | Q22: =ABS(_xlfn.NORM.INV(RAND(),$B$2,SQRT($B$3))) -> 0.00039319354 | R22: =ABS(_xlfn.NORM.INV(RAND(),$B$2,SQRT($B$3))) -> 0.0001153633 | S22: =ABS(_xlfn.NORM.INV(RAND(),$B$2,SQRT($B$3))) -> 2.6643346e-05 | T22: =ABS(_xlfn.NORM.INV(RAND(),$B$2,SQRT($B$3))) -> 0.00035323231 | U22: =ABS(_xlfn.NORM.INV(RAND(),$B$2,SQRT($B$3))) -> 0.00032814418 | ... CW22: =ABS(_xlfn.NORM.INV(RAND(),$B$2,SQRT($B$3))) -> 0.00019601583
N23: =ABS(_xlfn.NORM.INV(RAND(),$B$2,SQRT($B$3))) -> 0.00044140984 | O23: =ABS(_xlfn.NORM.INV(RAND(),$B$2,SQRT($B$3))) -> 0.0001650641 | P23: =ABS(_xlfn.NORM.INV(RAND(),$B$2,SQRT($B$3))) -> 0.00033135109 | Q23: =ABS(_xlfn.NORM.INV(RAND(),$B$2,SQRT($B$3))) -> 8.7359353e-05 | R23: =ABS(_xlfn.NORM.INV(RAND(),$B$2,SQRT($B$3))) -> 5.2994934e-05 | S23: =ABS(_xlfn.NORM.INV(RAND(),$B$2,SQRT($B$3))) -> 0.00064399845 | T23: =ABS(_xlfn.NORM.INV(RAND(),$B$2,SQRT($B$3))) -> 0.00026792462 | U23: =ABS(_xlfn.NORM.INV(RAND(),$B$2,SQRT($B$3))) -> 0.00068494032 | ... CW23: =ABS(_xlfn.NORM.INV(RAND(),$B$2,SQRT($B$3))) -> 5.1193359e-05
N24: =ABS(_xlfn.NORM.INV(RAND(),$B$2,SQRT($B$3))) -> 7.5397961e-05 | O24: =ABS(_xlfn.NORM.INV(RAND(),$B$2,SQRT($B$3))) -> 0.00042814254 | P24: =ABS(_xlfn.NORM.INV(RAND(),$B$2,SQRT($B$3))) -> 0.00048112492 | Q24: =ABS(_xlfn.NORM.INV(RAND(),$B$2,SQRT($B$3))) -> 0.0011962308 | R24: =ABS(_xlfn.NORM.INV(RAND(),$B$2,SQRT($B$3))) -> 0.00037912642 | S24: =ABS(_xlfn.NORM.INV(RAND(),$B$2,SQRT($B$3))) -> 8.0771926e-05 | T24: =ABS(_xlfn.NORM.INV(RAND(),$B$2,SQRT($B$3))) -> 0.00024233001 | U24: =ABS(_xlfn.NORM.INV(RAND(),$B$2,SQRT($B$3))) -> 0.00041981155 | ... CW24: =ABS(_xlfn.NORM.INV(RAND(),$B$2,SQRT($B$3))) -> 9.2043879e-05
N25: =ABS(_xlfn.NORM.INV(RAND(),$B$2,SQRT($B$3))) -> 0.00041164341 | O25: =ABS(_xlfn.NORM.INV(RAND(),$B$2,SQRT($B$3))) -> 0.00076583107 | P25: =ABS(_xlfn.NORM.INV(RAND(),$B$2,SQRT($B$3))) -> 0.00032044548 | Q25: =ABS(_xlfn.NORM.INV(RAND(),$B$2,SQRT($B$3))) -> 0.00048588475 | R25: =ABS(_xlfn.NORM.INV(RAND(),$B$2,SQRT($B$3))) -> 0.00052926278 | S25: =ABS(_xlfn.NORM.INV(RAND(),$B$2,SQRT($B$3))) -> 1.2390287e-06 | T25: =ABS(_xlfn.NORM.INV(RAND(),$B$2,SQRT($B$3))) -> 0.00051414355 | U25: =ABS(_xlfn.NORM.INV(RAND(),$B$2,SQRT($B$3))) -> 0.00033677738 | ... CW25: =ABS(_xlfn.NORM.INV(RAND(),$B$2,SQRT($B$3))) -> 5.7208435e-05
N26: =ABS(_xlfn.NORM.INV(RAND(),$B$2,SQRT($B$3))) -> 5.1673117e-05 | O26: =ABS(_xlfn.NORM.INV(RAND(),$B$2,SQRT($B$3))) -> 0.00032553316 | P26: =ABS(_xlfn.NORM.INV(RAND(),$B$2,SQRT($B$3))) -> 0.00045298013 | Q26: =ABS(_xlfn.NORM.INV(RAND(),$B$2,SQRT($B$3))) -> 0.00035057051 | R26: =ABS(_xlfn.NORM.INV(RAND(),$B$2,SQRT($B$3))) -> 0.00025110533 | S26: =ABS(_xlfn.NORM.INV(RAND(),$B$2,SQRT($B$3))) -> 4.7213631e-05 | T26: =ABS(_xlfn.NORM.INV(RAND(),$B$2,SQRT($B$3))) -> 0.00022792641 | U26: =ABS(_xlfn.NORM.INV(RAND(),$B$2,SQRT($B$3))) -> 3.8001944e-05 | ... CW26: =ABS(_xlfn.NORM.INV(RAND(),$B$2,SQRT($B$3))) -> 0.00022683541
... N249: =ABS(_xlfn.NORM.INV(RAND(),$B$2,SQRT($B$3))) -> 0.00029915312 | O249: =ABS(_xlfn.NORM.INV(RAND(),$B$2,SQRT($B$3))) -> 0.00012304721 | P249: =ABS(_xlfn.NORM.INV(RAND(),$B$2,SQRT($B$3))) -> 0.00061170674 | Q249: =ABS(_xlfn.NORM.INV(RAND(),$B$2,SQRT($B$3))) -> 0.00036780586 | R249: =ABS(_xlfn.NORM.INV(RAND(),$B$2,SQRT($B$3))) -> 0.0008944569 | S249: =ABS(_xlfn.NORM.INV(RAND(),$B$2,SQRT($B$3))) -> 0.00016897712 | T249: =ABS(_xlfn.NORM.INV(RAND(),$B$2,SQRT($B$3))) -> 0.00015962891 | U249: =ABS(_xlfn.NORM.INV(RAND(),$B$2,SQRT($B$3))) -> 0.00030371124 | ... CW249: =ABS(_xlfn.NORM.INV(RAND(),$B$2,SQRT($B$3))) -> 0.00028786295

Sheet Sheet2
A3: Magnitude | B3: 0 | F3: ='Volume Values'!B2 -> 3.5e-07
A4: Scale | B4: 1
A5: Offset | B5: =-LOG10(F3) -> 6.455932
J9: =LOG10('Volume Values'!N15+$B$3)*$B$4+$B$5 -> 2.5925171 | K9: =LOG10('Volume Values'!O15+$B$3)*$B$4+$B$5 -> 2.9263835 | L9: =LOG10('Volume Values'!P15+$B$3)*$B$4+$B$5 -> 2.7811267 | M9: =LOG10('Volume Values'!Q15+$B$3)*$B$4+$B$5 -> 2.7059756 | N9: =LOG10('Volume Values'!R15+$B$3)*$B$4+$B$5 -> 2.6223827 | O9: =LOG10('Volume Values'!S15+$B$3)*$B$4+$B$5 -> 3.1562884 | P9: =LOG10('Volume Values'!T15+$B$3)*$B$4+$B$5 -> 3.130717 | Q9: =LOG10('Volume Values'!U15+$B$3)*$B$4+$B$5 -> 2.3926948 | ... CS9: =LOG10('Volume Values'!CW15+$B$3)*$B$4+$B$5 -> 3.0259239
J10: =LOG10('Volume Values'!N16+$B$3)*$B$4+$B$5 -> 2.114008 | K10: =LOG10('Volume Values'!O16+$B$3)*$B$4+$B$5 -> 3.1071596 | L10: =LOG10('Volume Values'!P16+$B$3)*$B$4+$B$5 -> 3.1222685 | M10: =LOG10('Volume Values'!Q16+$B$3)*$B$4+$B$5 -> 2.8919802 | N10: =LOG10('Volume Values'!R16+$B$3)*$B$4+$B$5 -> 3.0237206 | O10: =LOG10('Volume Values'!S16+$B$3)*$B$4+$B$5 -> 2.7903765 | P10: =LOG10('Volume Values'!T16+$B$3)*$B$4+$B$5 -> 2.9576415 | Q10: =LOG10('Volume Values'!U16+$B$3)*$B$4+$B$5 -> 2.7959133 | ... CS10: =LOG10('Volume Values'!CW16+$B$3)*$B$4+$B$5 -> 2.4107404
J11: =LOG10('Volume Values'!N17+$B$3)*$B$4+$B$5 -> 2.8517306 | K11: =LOG10('Volume Values'!O17+$B$3)*$B$4+$B$5 -> 2.7891399 | L11: =LOG10('Volume Values'!P17+$B$3)*$B$4+$B$5 -> 3.1459427 | M11: =LOG10('Volume Values'!Q17+$B$3)*$B$4+$B$5 -> 1.5102796 | N11: =LOG10('Volume Values'!R17+$B$3)*$B$4+$B$5 -> 2.7996378 | O11: =LOG10('Volume Values'!S17+$B$3)*$B$4+$B$5 -> 3.0095377 | P11: =LOG10('Volume Values'!T17+$B$3)*$B$4+$B$5 -> 3.0024069 | Q11: =LOG10('Volume Values'!U17+$B$3)*$B$4+$B$5 -> 3.1397036 | ... CS11: =LOG10('Volume Values'!CW17+$B$3)*$B$4+$B$5 -> 3.3209747
J12: =LOG10('Volume Values'!N18+$B$3)*$B$4+$B$5 -> 2.5725072 | K12: =LOG10('Volume Values'!O18+$B$3)*$B$4+$B$5 -> 3.2050973 | L12: =LOG10('Volume Values'!P18+$B$3)*$B$4+$B$5 -> 3.0570787 | M12: =LOG10('Volume Values'!Q18+$B$3)*$B$4+$B$5 -> 1.0905182 | N12: =LOG10('Volume Values'!R18+$B$3)*$B$4+$B$5 -> 3.3535624 | O12: =LOG10('Volume Values'!S18+$B$3)*$B$4+$B$5 -> 2.6598646 | P12: =LOG10('Volume Values'!T18+$B$3)*$B$4+$B$5 -> 3.2706904 | Q12: =LOG10('Volume Values'!U18+$B$3)*$B$4+$B$5 -> 3.1211479 | ... CS12: =LOG10('Volume Values'!CW18+$B$3)*$B$4+$B$5 -> 2.4768459
J13: =LOG10('Volume Values'!N19+$B$3)*$B$4+$B$5 -> 2.8073541 | K13: =LOG10('Volume Values'!O19+$B$3)*$B$4+$B$5 -> 2.7300067 | L13: =LOG10('Volume Values'!P19+$B$3)*$B$4+$B$5 -> 2.8800993 | M13: =LOG10('Volume Values'!Q19+$B$3)*$B$4+$B$5 -> 2.5788484 | N13: =LOG10('Volume Values'!R19+$B$3)*$B$4+$B$5 -> 2.4187776 | O13: =LOG10('Volume Values'!S19+$B$3)*$B$4+$B$5 -> 3.2005644 | P13: =LOG10('Volume Values'!T19+$B$3)*$B$4+$B$5 -> 2.5293911 | Q13: =LOG10('Volume Values'!U19+$B$3)*$B$4+$B$5 -> 2.4325626 | ... CS13: =LOG10('Volume Values'!CW19+$B$3)*$B$4+$B$5 -> 3.0235459
J14: =LOG10('Volume Values'!N20+$B$3)*$B$4+$B$5 -> 3.2279386 | K14: =LOG10('Volume Values'!O20+$B$3)*$B$4+$B$5 -> 1.9721751 | L14: =LOG10('Volume Values'!P20+$B$3)*$B$4+$B$5 -> 2.9605341 | M14: =LOG10('Volume Values'!Q20+$B$3)*$B$4+$B$5 -> 2.5747284 | N14: =LOG10('Volume Values'!R20+$B$3)*$B$4+$B$5 -> 1.8016081 | O14: =LOG10('Volume Values'!S20+$B$3)*$B$4+$B$5 -> 2.2419894 | P14: =LOG10('Volume Values'!T20+$B$3)*$B$4+$B$5 -> 2.4988987 | Q14: =LOG10('Volume Values'!U20+$B$3)*$B$4+$B$5 -> 2.7707726 | ... CS14: =LOG10('Volume Values'!CW20+$B$3)*$B$4+$B$5 -> 2.5112031
J15: =LOG10('Volume Values'!N21+$B$3)*$B$4+$B$5 -> 3.1239364 | K15: =LOG10('Volume Values'!O21+$B$3)*$B$4+$B$5 -> 2.5218876 | L15: =LOG10('Volume Values'!P21+$B$3)*$B$4+$B$5 -> 2.5259958 | M15: =LOG10('Volume Values'!Q21+$B$3)*$B$4+$B$5 -> 2.3622795 | N15: =LOG10('Volume Values'!R21+$B$3)*$B$4+$B$5 -> 2.2516784 | O15: =LOG10('Volume Values'!S21+$B$3)*$B$4+$B$5 -> 1.6316149 | P15: =LOG10('Volume Values'!T21+$B$3)*$B$4+$B$5 -> 3.0389156 | Q15: =LOG10('Volume Values'!U21+$B$3)*$B$4+$B$5 -> 2.5227889 | ... CS15: =LOG10('Volume Values'!CW21+$B$3)*$B$4+$B$5 -> 1.6762087
J16: =LOG10('Volume Values'!N22+$B$3)*$B$4+$B$5 -> 2.9988111 | K16: =LOG10('Volume Values'!O22+$B$3)*$B$4+$B$5 -> 2.9821726 | L16: =LOG10('Volume Values'!P22+$B$3)*$B$4+$B$5 -> 3.2822962 | M16: =LOG10('Volume Values'!Q22+$B$3)*$B$4+$B$5 -> 3.0505383 | N16: =LOG10('Volume Values'!R22+$B$3)*$B$4+$B$5 -> 2.5179996 | O16: =LOG10('Volume Values'!S22+$B$3)*$B$4+$B$5 -> 1.8815207 | P16: =LOG10('Volume Values'!T22+$B$3)*$B$4+$B$5 -> 3.0039924 | Q16: =LOG10('Volume Values'!U22+$B$3)*$B$4+$B$5 -> 2.9719967 | ... CS16: =LOG10('Volume Values'!CW22+$B$3)*$B$4+$B$5 -> 2.7482231
J17: =LOG10('Volume Values'!N23+$B$3)*$B$4+$B$5 -> 3.100774 | K17: =LOG10('Volume Values'!O23+$B$3)*$B$4+$B$5 -> 2.6735846 | L17: =LOG10('Volume Values'!P23+$B$3)*$B$4+$B$5 -> 2.9762204 | M17: =LOG10('Volume Values'!Q23+$B$3)*$B$4+$B$5 -> 2.3972414 | N17: =LOG10('Volume Values'!R23+$B$3)*$B$4+$B$5 -> 2.1801663 | O17: =LOG10('Volume Values'!S23+$B$3)*$B$4+$B$5 -> 3.2648168 | P17: =LOG10('Volume Values'!T23+$B$3)*$B$4+$B$5 -> 2.8839446 | Q17: =LOG10('Volume Values'!U23+$B$3)*$B$4+$B$5 -> 3.2915847 | ... CS17: =LOG10('Volume Values'!CW23+$B$3)*$B$4+$B$5 -> 2.1651456
J18: =LOG10('Volume Values'!N24+$B$3)*$B$4+$B$5 -> 2.3332916 | K18: =LOG10('Volume Values'!O24+$B$3)*$B$4+$B$5 -> 3.0875203 | L18: =LOG10('Volume Values'!P24+$B$3)*$B$4+$B$5 -> 3.1381898 | M18: =LOG10('Volume Values'!Q24+$B$3)*$B$4+$B$5 -> 3.5337469 | N18: =LOG10('Volume Values'!R24+$B$3)*$B$4+$B$5 -> 3.034716 | O18: =LOG10('Volume Values'!S24+$B$3)*$B$4+$B$5 -> 2.3631924 | P18: =LOG10('Volume Values'!T24+$B$3)*$B$4+$B$5 -> 2.8403392 | Q18: =LOG10('Volume Values'!U24+$B$3)*$B$4+$B$5 -> 3.0789863 | ... CS18: =LOG10('Volume Values'!CW24+$B$3)*$B$4+$B$5 -> 2.4199269
J19: =LOG10('Volume Values'!N25+$B$3)*$B$4+$B$5 -> 3.0704531 | K19: =LOG10('Volume Values'!O25+$B$3)*$B$4+$B$5 -> 3.3400649 | L19: =LOG10('Volume Values'!P25+$B$3)*$B$4+$B$5 -> 2.9616861 | M19: =LOG10('Volume Values'!Q25+$B$3)*$B$4+$B$5 -> 3.1424652 | N19: =LOG10('Volume Values'!R25+$B$3)*$B$4+$B$5 -> 3.1796033 | O19: =LOG10('Volume Values'!S25+$B$3)*$B$4+$B$5 -> 0.54901331 | P19: =LOG10('Volume Values'!T25+$B$3)*$B$4+$B$5 -> 3.1670163 | Q19: =LOG10('Volume Values'!U25+$B$3)*$B$4+$B$5 -> 2.9832749 | ... CS19: =LOG10('Volume Values'!CW25+$B$3)*$B$4+$B$5 -> 2.213392
J20: =LOG10('Volume Values'!N26+$B$3)*$B$4+$B$5 -> 2.1691966 | K20: =LOG10('Volume Values'!O26+$B$3)*$B$4+$B$5 -> 2.9685272 | L20: =LOG10('Volume Values'!P26+$B$3)*$B$4+$B$5 -> 3.1120111 | M20: =LOG10('Volume Values'!Q26+$B$3)*$B$4+$B$5 -> 3.0007073 | N20: =LOG10('Volume Values'!R26+$B$3)*$B$4+$B$5 -> 2.8557879 | O20: =LOG10('Volume Values'!S26+$B$3)*$B$4+$B$5 -> 2.1299994 | P20: =LOG10('Volume Values'!T26+$B$3)*$B$4+$B$5 -> 2.8137266 | Q20: =LOG10('Volume Values'!U26+$B$3)*$B$4+$B$5 -> 2.0357378 | ... CS20: =LOG10('Volume Values'!CW26+$B$3)*$B$4+$B$5 -> 2.8116428
... J24: =LOG10('Volume Values'!N30+$B$3)*$B$4+$B$5 -> 3.0639639 | K24: =LOG10('Volume Values'!O30+$B$3)*$B$4+$B$5 -> 3.1044193 | L24: =LOG10('Volume Values'!P30+$B$3)*$B$4+$B$5 -> 2.7477331 | M24: =LOG10('Volume Values'!Q30+$B$3)*$B$4+$B$5 -> 3.3840355 | N24: =LOG10('Volume Values'!R30+$B$3)*$B$4+$B$5 -> 2.249009 | O24: =LOG10('Volume Values'!S30+$B$3)*$B$4+$B$5 -> 2.0551156 | P24: =LOG10('Volume Values'!T30+$B$3)*$B$4+$B$5 -> 3.0283401 | Q24: =LOG10('Volume Values'!U30+$B$3)*$B$4+$B$5 -> 2.7642091 | ... CS24: =LOG10('Volume Values'!CW30+$B$3)*$B$4+$B$5 -> 2.4092663
A25: =LOG10(F3) -> -6.455932 | J25: =LOG10('Volume Values'!N31+$B$3)*$B$4+$B$5 -> 2.6665507 | K25: =LOG10('Volume Values'!O31+$B$3)*$B$4+$B$5 -> 2.9016727 | L25: =LOG10('Volume Values'!P31+$B$3)*$B$4+$B$5 -> 3.0802057 | M25: =LOG10('Volume Values'!Q31+$B$3)*$B$4+$B$5 -> 2.5241 | N25: =LOG10('Volume Values'!R31+$B$3)*$B$4+$B$5 -> 3.0217844 | O25: =LOG10('Volume Values'!S31+$B$3)*$B$4+$B$5 -> 2.4007666 | P25: =LOG10('Volume Values'!T31+$B$3)*$B$4+$B$5 -> 2.5197067 | Q25: =LOG10('Volume Values'!U31+$B$3)*$B$4+$B$5 -> 2.3873574 | ... CS25: =LOG10('Volume Values'!CW31+$B$3)*$B$4+$B$5 -> 3.101239
J26: =LOG10('Volume Values'!N32+$B$3)*$B$4+$B$5 -> 3.0724172 | K26: =LOG10('Volume Values'!O32+$B$3)*$B$4+$B$5 -> 3.2627382 | L26: =LOG10('Volume Values'!P32+$B$3)*$B$4+$B$5 -> 2.7908416 | M26: =LOG10('Volume Values'!Q32+$B$3)*$B$4+$B$5 -> 2.2140845 | N26: =LOG10('Volume Values'!R32+$B$3)*$B$4+$B$5 -> 2.86878 | O26: =LOG10('Volume Values'!S32+$B$3)*$B$4+$B$5 -> 3.3719349 | P26: =LOG10('Volume Values'!T32+$B$3)*$B$4+$B$5 -> 2.7241177 | Q26: =LOG10('Volume Values'!U32+$B$3)*$B$4+$B$5 -> 3.2038089 | ... CS26: =LOG10('Volume Values'!CW32+$B$3)*$B$4+$B$5 -> 2.6647858
J27: =LOG10('Volume Values'!N33+$B$3)*$B$4+$B$5 -> 3.0303878 | K27: =LOG10('Volume Values'!O33+$B$3)*$B$4+$B$5 -> 3.083117 | L27: =LOG10('Volume Values'!P33+$B$3)*$B$4+$B$5 -> 2.4522734 | M27: =LOG10('Volume Values'!Q33+$B$3)*$B$4+$B$5 -> 2.8643167 | N27: =LOG10('Volume Values'!R33+$B$3)*$B$4+$B$5 -> 1.9811066 | O27: =LOG10('Volume Values'!S33+$B$3)*$B$4+$B$5 -> 2.118366 | P27: =LOG10('Volume Values'!T33+$B$3)*$B$4+$B$5 -> 3.0526422 | Q27: =LOG10('Volume Values'!U33+$B$3)*$B$4+$B$5 -> 3.074917 | ... CS27: =LOG10('Volume Values'!CW33+$B$3)*$B$4+$B$5 -> 2.508392
J28: =LOG10('Volume Values'!N34+$B$3)*$B$4+$B$5 -> 2.3872186 | K28: =LOG10('Volume Values'!O34+$B$3)*$B$4+$B$5 -> 2.4745071 | L28: =LOG10('Volume Values'!P34+$B$3)*$B$4+$B$5 -> 2.8857564 | M28: =LOG10('Volume Values'!Q34+$B$3)*$B$4+$B$5 -> 2.3647349 | N28: =LOG10('Volume Values'!R34+$B$3)*$B$4+$B$5 -> 1.415363 | O28: =LOG10('Volume Values'!S34+$B$3)*$B$4+$B$5 -> 3.1189396 | P28: =LOG10('Volume Values'!T34+$B$3)*$B$4+$B$5 -> 2.5352296 | Q28: =LOG10('Volume Values'!U34+$B$3)*$B$4+$B$5 -> 2.4823324 | ... CS28: =LOG10('Volume Values'!CW34+$B$3)*$B$4+$B$5 -> 2.8941056
J29: =LOG10('Volume Values'!N35+$B$3)*$B$4+$B$5 -> 3.3075272 | K29: =LOG10('Volume Values'!O35+$B$3)*$B$4+$B$5 -> 2.5476926 | L29: =LOG10('Volume Values'!P35+$B$3)*$B$4+$B$5 -> 2.6316296 | M29: =LOG10('Volume Values'!Q35+$B$3)*$B$4+$B$5 -> 3.035876 | N29: =LOG10('Volume Values'!R35+$B$3)*$B$4+$B$5 -> 3.0272498 | O29: =LOG10('Volume Values'!S35+$B$3)*$B$4+$B$5 -> 2.1628235 | P29: =LOG10('Volume Values'!T35+$B$3)*$B$4+$B$5 -> 3.2680496 | Q29: =LOG10('Volume Values'!U35+$B$3)*$B$4+$B$5 -> 3.087063 | ... CS29: =LOG10('Volume Values'!CW35+$B$3)*$B$4+$B$5 -> 1.9889143
J30: =LOG10('Volume Values'!N36+$B$3)*$B$4+$B$5 -> 2.9003286 | K30: =LOG10('Volume Values'!O36+$B$3)*$B$4+$B$5 -> 2.9049687 | L30: =LOG10('Volume Values'!P36+$B$3)*$B$4+$B$5 -> 3.1853195 | M30: =LOG10('Volume Values'!Q36+$B$3)*$B$4+$B$5 -> 2.8175498 | N30: =LOG10('Volume Values'!R36+$B$3)*$B$4+$B$5 -> 2.2970012 | O30: =LOG10('Volume Values'!S36+$B$3)*$B$4+$B$5 -> 3.2299397 | P30: =LOG10('Volume Values'!T36+$B$3)*$B$4+$B$5 -> 2.8635329 | Q30: =LOG10('Volume Values'!U36+$B$3)*$B$4+$B$5 -> 2.097834 | ... CS30: =LOG10('Volume Values'!CW36+$B$3)*$B$4+$B$5 -> 3.2308237
J31: =LOG10('Volume Values'!N37+$B$3)*$B$4+$B$5 -> 2.9321403 | K31: =LOG10('Volume Values'!O37+$B$3)*$B$4+$B$5 -> 2.3592081 | L31: =LOG10('Volume Values'!P37+$B$3)*$B$4+$B$5 -> 3.3283888 | M31: =LOG10('Volume Values'!Q37+$B$3)*$B$4+$B$5 -> 2.4898813 | N31: =LOG10('Volume Values'!R37+$B$3)*$B$4+$B$5 -> 2.6636476 | O31: =LOG10('Volume Values'!S37+$B$3)*$B$4+$B$5 -> 2.2323459 | P31: =LOG10('Volume Values'!T37+$B$3)*$B$4+$B$5 -> 2.9419021 | Q31: =LOG10('Volume Values'!U37+$B$3)*$B$4+$B$5 -> 3.1776676 | ... CS31: =LOG10('Volume Values'!CW37+$B$3)*$B$4+$B$5 -> 2.8506861
J32: =LOG10('Volume Values'!N38+$B$3)*$B$4+$B$5 -> 2.7683253 | K32: =LOG10('Volume Values'!O38+$B$3)*$B$4+$B$5 -> 2.809452 | L32: =LOG10('Volume Values'!P38+$B$3)*$B$4+$B$5 -> 2.9767676 | M32: =LOG10('Volume Values'!Q38+$B$3)*$B$4+$B$5 -> 2.7911144 | N32: =LOG10('Volume Values'!R38+$B$3)*$B$4+$B$5 -> 2.516741 | O32: =LOG10('Volume Values'!S38+$B$3)*$B$4+$B$5 -> 2.9132594 | P32: =LOG10('Volume Values'!T38+$B$3)*$B$4+$B$5 -> 3.0372942 | Q32: =LOG10('Volume Values'!U38+$B$3)*$B$4+$B$5 -> 2.8230055 | ... CS32: =LOG10('Volume Values'!CW38+$B$3)*$B$4+$B$5 -> 2.2299854
J33: =LOG10('Volume Values'!N39+$B$3)*$B$4+$B$5 -> 3.2761752 | K33: =LOG10('Volume Values'!O39+$B$3)*$B$4+$B$5 -> 2.0486223 | L33: =LOG10('Volume Values'!P39+$B$3)*$B$4+$B$5 -> 2.6094895 | M33: =LOG10('Volume Values'!Q39+$B$3)*$B$4+$B$5 -> 2.9203556 | N33: =LOG10('Volume Values'!R39+$B$3)*$B$4+$B$5 -> 3.3257332 | O33: =LOG10('Volume Values'!S39+$B$3)*$B$4+$B$5 -> 2.9573852 | P33: =LOG10('Volume Values'!T39+$B$3)*$B$4+$B$5 -> 2.7847062 | Q33: =LOG10('Volume Values'!U39+$B$3)*$B$4+$B$5 -> 2.3736454 | ... CS33: =LOG10('Volume Values'!CW39+$B$3)*$B$4+$B$5 -> 3.2992834
J34: =LOG10('Volume Values'!N40+$B$3)*$B$4+$B$5 -> 3.1204303 | K34: =LOG10('Volume Values'!O40+$B$3)*$B$4+$B$5 -> 3.0186259 | L34: =LOG10('Volume Values'!P40+$B$3)*$B$4+$B$5 -> 3.0315286 | M34: =LOG10('Volume Values'!Q40+$B$3)*$B$4+$B$5 -> 2.74936 | N34: =LOG10('Volume Values'!R40+$B$3)*$B$4+$B$5 -> 2.7157626 | O34: =LOG10('Volume Values'!S40+$B$3)*$B$4+$B$5 -> 2.6693923 | P34: =LOG10('Volume Values'!T40+$B$3)*$B$4+$B$5 -> 2.5628974 | Q34: =LOG10('Volume Values'!U40+$B$3)*$B$4+$B$5 -> 3.1241836 | ... CS34: =LOG10('Volume Values'!CW40+$B$3)*$B$4+$B$5 -> 3.1722215
J35: =LOG10('Volume Values'!N41+$B$3)*$B$4+$B$5 -> 2.8251521 | K35: =LOG10('Volume Values'!O41+$B$3)*$B$4+$B$5 -> 2.2917871 | L35: =LOG10('Volume Values'!P41+$B$3)*$B$4+$B$5 -> 2.8315584 | M35: =LOG10('Volume Values'!Q41+$B$3)*$B$4+$B$5 -> 2.1643252 | N35: =LOG10('Volume Values'!R41+$B$3)*$B$4+$B$5 -> 3.0237692 | O35: =LOG10('Volume Values'!S41+$B$3)*$B$4+$B$5 -> 2.9573872 | P35: =LOG10('Volume Values'!T41+$B$3)*$B$4+$B$5 -> 3.0700665 | Q35: =LOG10('Volume Values'!U41+$B$3)*$B$4+$B$5 -> 2.5409014 | ... CS35: =LOG10('Volume Values'!CW41+$B$3)*$B$4+$B$5 -> 2.3888772
J36: =LOG10('Volume Values'!N42+$B$3)*$B$4+$B$5 -> 3.1439017 | K36: =LOG10('Volume Values'!O42+$B$3)*$B$4+$B$5 -> 3.0015524 | L36: =LOG10('Volume Values'!P42+$B$3)*$B$4+$B$5 -> 2.4950611 | M36: =LOG10('Volume Values'!Q42+$B$3)*$B$4+$B$5 -> 2.5412356 | N36: =LOG10('Volume Values'!R42+$B$3)*$B$4+$B$5 -> 3.3712659 | O36: =LOG10('Volume Values'!S42+$B$3)*$B$4+$B$5 -> 2.6350246 | P36: =LOG10('Volume Values'!T42+$B$3)*$B$4+$B$5 -> 2.6570003 | Q36: =LOG10('Volume Values'!U42+$B$3)*$B$4+$B$5 -> 3.1369503 | ... CS36: =LOG10('Volume Values'!CW42+$B$3)*$B$4+$B$5 -> 3.042858
J37: =LOG10('Volume Values'!N43+$B$3)*$B$4+$B$5 -> 2.5095806 | K37: =LOG10('Volume Values'!O43+$B$3)*$B$4+$B$5 -> 3.1266753 | L37: =LOG10('Volume Values'!P43+$B$3)*$B$4+$B$5 -> 3.0681487 | M37: =LOG10('Volume Values'!Q43+$B$3)*$B$4+$B$5 -> 2.9993621 | N37: =LOG10('Volume Values'!R43+$B$3)*$B$4+$B$5 -> 2.0425586 | O37: =LOG10('Volume Values'!S43+$B$3)*$B$4+$B$5 -> 2.6401009 | P37: =LOG10('Volume Values'!T43+$B$3)*$B$4+$B$5 -> 2.7889618 | Q37: =LOG10('Volume Values'!U43+$B$3)*$B$4+$B$5 -> 3.0310704 | ... CS37: =LOG10('Volume Values'!CW43+$B$3)*$B$4+$B$5 -> 2.9019179
... J243: =LOG10('Volume Values'!N249+$B$3)*$B$4+$B$5 -> 2.9318255 | K243: =LOG10('Volume Values'!O249+$B$3)*$B$4+$B$5 -> 2.5460037 | L243: =LOG10('Volume Values'!P249+$B$3)*$B$4+$B$5 -> 3.2424752 | M243: =LOG10('Volume Values'!Q249+$B$3)*$B$4+$B$5 -> 3.0215506 | N243: =LOG10('Volume Values'!R249+$B$3)*$B$4+$B$5 -> 3.4074914 | O243: =LOG10('Volume Values'!S249+$B$3)*$B$4+$B$5 -> 2.6837599 | P243: =LOG10('Volume Values'!T249+$B$3)*$B$4+$B$5 -> 2.6590435 | Q243: =LOG10('Volume Values'!U249+$B$3)*$B$4+$B$5 -> 2.9383928 | ... CS243: =LOG10('Volume Values'!CW249+$B$3)*$B$4+$B$5 -> 2.9151177
